Workbook

Sheet START HERE
A1: Vibe Add-Ons ✦
A3: Your life has side quests. Your planner should too.
A5: HEY QUEEN, YOUR LIFE GETS TO BE SPECIFIC ♡
A6: The main Vibe Dashboard holds the everyday big picture, but some parts of life deserve their own little world. The books you devour, trips you plan, memories you want to keep, shows you binge, gifts you don’t want to forget — those things matter too, but they don’t all need to crowd your core system.
A8: That’s why the Vibe Add-Ons exist. They’re modular little systems you can use on their own or slide into your Dashboard when they fit your season. Add what feels useful, leave what doesn’t, and let your system grow with you instead of forcing your life into somebody else’s planner.
A10: Use one. Use all of them. Skip a few. Come back later. The goal isn’t more pages — it’s a planner that actually feels like yours. ✦
A13: WHAT’S IN YOUR VIBE? ♡
A14: Reading Vibe | B14: Book catalog + a duplicable discussion/reflection page
A15: Adventure Vibe | B15: Adventure tracker + a duplicable memory page
A16: Sticker Vibe | B16: Sticker collection catalog + digital sticker board
A17: Screen Vibe | B17: Movie + TV watchlist, progress, ratings, and mini reviews
A18: Travel Vibe | B18: Trip dashboard + trip details + full packing checklist
A19: Gift + Wishlist Vibe | B19: Gifts to give + your own wishlist in one place
A22: HOW TO USE THESE ✦
A23: Use the add-ons as standalone mini systems, or copy the sheet(s) you want into The Vibe Dashboard. Reflection, discussion, memory, and trip-detail pages are meant to be duplicated whenever you need a fresh one.
A24: Keep one clean original copy before you start customizing so you always have a fresh version to come back to.
A26: Make it useful. Make it pretty. Make it yours. ♡

Sheet READING
A1: Reading Vibe ♡
A3: Your shelves, stories, and little literary obsessions — all in one place.
A4: Dashboard Add-On ✦ Copy this tab into The Vibe Dashboard or use it all by itself.
A6: YEAR | C6: READING GOAL | E6: FINISHED | G6: CURRENTLY READING | I6: TBR | K6: AVG RATING | M6: PROGRESS
A7: =YEAR(TODAY()) -> 2026 | C7: 24 | E7: =COUNTIFS($J$14:$J$250,">="&DATE($A$7,1,1),$J$14:$J$250,"<="&DATE($A$7,12,31),$F$14:$F$250,"Finished") -> 0 | G7: =COUNTIF($F$14:$F$250,"Reading") -> 1 | I7: =COUNTIF($F$14:$F$250,"TBR") -> 1 | K7: =IFERROR(AVERAGEIF($F$14:$F$250,"Finished",$G$14:$G$250),"") | M7: =IFERROR(__xludf.DUMMYFUNCTION("IF($C$7=0,"""",SPARKLINE(MIN($E$7/$C$7,1),{""charttype"",""bar"";""max"",1;""color1"",""#D5AE5E""}))"),"")
A9: CURRENT READ ♡ | H9: NEXT UP ✦
A10: {=IFERROR(INDEX($A$14:$A$250,MATCH("Reading",$F$14:$F$250,0)),"Add a current read ♡")} -> Crank | H10: {=IFERROR(INDEX($A$14:$A$250,MATCH("TBR",$F$14:$F$250,0)),"Add something to your TBR ✦")} -> Burned
A12: {=IFERROR("by "&INDEX($B$14:$B$250,MATCH("Reading",$F$14:$F$250,0)),"")} -> by Ellen Hopkins | H12: {=IFERROR("by "&INDEX($B$14:$B$250,MATCH("TBR",$F$14:$F$250,0)),"")} -> by Ellen Hopkins
A13: BOOK TITLE | B13: AUTHOR | C13: SERIES | D13: GENRE | E13: FORMAT | F13: STATUS | G13: RATING | H13: LENGTH | I13: START DATE | J13: FINISH DATE | K13: SOURCE | L13: FAVORITE | M13: REVIEW / NOTES | N13: LINK
A14: Crank | B14: Ellen Hopkins | C14: Crank | D14: YA | E14: Print | F14: Reading | G14: 5 | L14: TRUE
A15: Burned | B15: Ellen Hopkins | C15: Crank | D15: YA | E15: Audiobook | F15: TBR | L15: FALSE
L16: FALSE
L17: FALSE
L18: FALSE
L19: FALSE
L20: FALSE
L21: FALSE
L22: FALSE
L23: FALSE
L24: FALSE
L25: FALSE
L26: FALSE
L27: FALSE
... L250: FALSE

Sheet READING DISCUSSION
A1: Reading Vibe Discussion ♡
A3: A little space to sit with the story after the last page.
A4: Choose a title from Reading Vibe. Duplicate this tab for each book if you want to keep individual discussion pages. ✦
A6: BOOK | B6: Crank | G6: RATING | H6: {=IFERROR(INDEX(READING!$G$14:$G$250,MATCH($B$6,READING!$A$14:$A$250,0)),"")} -> 5 | I6: FAVORITE? | J6: {=IFERROR(IF(INDEX(READING!$L$14:$L$250,MATCH($B$6,READING!$A$14:$A$250,0)),"♡ Yes",""),"")} -> ♡ Yes
A7: AUTHOR | B7: {=IFERROR(INDEX(READING!$B$14:$B$250,MATCH($B$6,READING!$A$14:$A$250,0)),"")} -> Ellen Hopkins | G7: FINISHED | H7: {=IFERROR(INDEX(READING!$J$14:$J$250,MATCH($B$6,READING!$A$14:$A$250,0)),"")}
A9: THE BOOK AT A GLANCE ✦
A10: One-sentence takeaway — what was this book really about to you?
A14: WHAT STAYED WITH ME ♡
A15: Favorite quote / line ✦ | H15: Scene I keep thinking about ✦
A20: DIG A LITTLE DEEPER ✦
A21: Themes I noticed ✦ | H21: Character / relationship thoughts ✦
A26: What surprised me ✦ | H26: What challenged me ✦
A31: PERSONAL REFLECTION ♡
A32: What did this book make me think or feel about my own life?
A37: Would I recommend it? To who? ✦ | H37: Final thoughts / mini review ✦
A42: MY VERDICT ✦
A43: Overall vibe | E43: Reread? | F43: FALSE | G43: Recommend? | H43: FALSE | I43: Book Club Worthy? | J43: FALSE

Sheet ADVENTURE JOURNAL
A1: Adventure Vibe ♡
A3: Keep the plans, the places, and the stories worth remembering.
A4: Dashboard Add-On ✦ Use this as your adventure catalog, then duplicate Adventure Memory for the moments you want to keep.
A6: DONE | C6: PLANNED | E6: WISHLIST | G6: FAVORITES | I6: TOTAL SPENT | K6: AVG RATING | M6: NEXT UP
A7: =COUNTIF($C$14:$C$250,"Done") -> 0 | C7: =COUNTIF($C$14:$C$250,"Planned") -> 0 | E7: =COUNTIF($C$14:$C$250,"Wishlist") -> 0 | G7: =COUNTIF($J$14:$J$250,TRUE) -> 0 | I7: =SUM($H$14:$H$250) -> 0 | K7: =IFERROR(AVERAGEIF($C$14:$C$250,"Done",$I$14:$I$250),"") | M7: =IFERROR(__xludf.DUMMYFUNCTION("IFERROR(INDEX(SORT(FILTER({$E$14:$E$250,$A$14:$A$250},$C$14:$C$250=""Planned"",$E$14:$E$250>=TODAY()),1,TRUE),1,2),""Add a planned adventure ✦"")"),"Add a planned adventure ✦") -> Add a planned adventure ✦
A9: NEXT ADVENTURE ♡ | H9: LATEST MEMORY ✦
A10: =IFERROR(__xludf.DUMMYFUNCTION("IFERROR(INDEX(SORT(FILTER({$E$14:$E$250,$A$14:$A$250},$C$14:$C$250=""Planned"",$E$14:$E$250>=TODAY()),1,TRUE),1,2)&CHAR(10)&TEXT(INDEX(SORT(FILTER({$E$14:$E$250,$A$14:$A$250},$C$14:$C$250=""Planned"",$E$14:$E$250>=TODAY()),1,TRUE),1,1),""mmm d, yyyy""),"""&"Add a planned adventure ♡"")"),"Add a planned adventure ♡") -> Add a planned adventure ♡ | H10: =IFERROR(__xludf.DUMMYFUNCTION("IFERROR(INDEX(SORT(FILTER({$E$14:$E$250,$A$14:$A$250},$C$14:$C$250=""Done"",$E$14:$E$250<>""""),1,FALSE),1,2),""Your latest adventure will appear here ✦"")"),"Your latest adventure will appear here ✦") -> Your latest adventure will appear here ✦
A13: ADVENTURE | B13: TYPE | C13: STATUS | D13: LOCATION | E13: DATE | F13: WITH | G13: EST. COST | H13: ACTUAL COST | I13: RATING | J13: FAVORITE | K13: PHOTO / LINK | L13: BEST MOMENT | M13: DO AGAIN? | N13: NOTES
J14: FALSE | M14: FALSE
J15: FALSE | M15: FALSE
J16: FALSE | M16: FALSE
J17: FALSE | M17: FALSE
J18: FALSE | M18: FALSE
J19: FALSE | M19: FALSE
J20: FALSE | M20: FALSE
J21: FALSE | M21: FALSE
J22: FALSE | M22: FALSE
J23: FALSE | M23: FALSE
J24: FALSE | M24: FALSE
J25: FALSE | M25: FALSE
... J250: FALSE | M250: FALSE

Sheet ADVENTURE MEMORY
A1: Adventure Memory ♡
A3: The details fade. The feeling doesn’t have to.
A4: Choose an adventure from Adventure Vibe, then duplicate this tab if you want to keep a page for each memory. ✦
A6: ADVENTURE | G6: RATING | H6: {=IFERROR(INDEX('ADVENTURE JOURNAL'!$I$14:$I$250,MATCH($B$6,'ADVENTURE JOURNAL'!$A$14:$A$250,0)),"")} | I6: FAVORITE? | J6: {=IFERROR(IF(INDEX('ADVENTURE JOURNAL'!$J$14:$J$250,MATCH($B$6,'ADVENTURE JOURNAL'!$A$14:$A$250,0)),"♡ Yes",""),"")}
A7: LOCATION | B7: {=IFERROR(INDEX('ADVENTURE JOURNAL'!$D$14:$D$250,MATCH($B$6,'ADVENTURE JOURNAL'!$A$14:$A$250,0)),"")} | E7: DATE | F7: {=IFERROR(INDEX('ADVENTURE JOURNAL'!$E$14:$E$250,MATCH($B$6,'ADVENTURE JOURNAL'!$A$14:$A$250,0)),"")} | H7: WITH | I7: {=IFERROR(INDEX('ADVENTURE JOURNAL'!$F$14:$F$250,MATCH($B$6,'ADVENTURE JOURNAL'!$A$14:$A$250,0)),"")}
A8: ♡ Don’t overthink it — a sentence, a tiny detail, a link, or a whole story all count. Fill what matters and leave the rest.
A9: THE ADVENTURE AT A GLANCE ✦
A10: What did we do? What made this one worth remembering?
A14: BEST MOMENT ♡ | H14: FUNNIEST / MOST UNEXPECTED ✦
A15: BEST MOMENT ♡ — what would you replay if you could? | H15: FUNNIEST / MOST UNEXPECTED ✦ — what caught you off guard?
A16: Start with the moment itself — what happened, who was there, and why did it hit? | H16: The funny, weird, unplanned thing you’ll still be telling people later…
A22: SENSORY SNAPSHOT ✦
A23: WHAT I CAN STILL SEE + HEAR ♡ | H23: TASTE / SMELL / FEEL ✦
A24: The view, colors, weather, music, voices, light, background noise… | H24: Food, perfume, salt air, cold wind, warm sun, textures — what brings you right back?
A30: WHAT SURPRISED ME ✦ — what wasn’t what you expected? | H30: WHAT I LEARNED ♡ — about the place, people, or myself
A31: What was better, stranger, harder, sweeter, or totally different than you pictured? | H31: About the place, the people, the plan — or yourself. Tiny lessons count too.
A37: PEOPLE + CONNECTION ✦ — who made this memory better? | H37: THE LITTLE FAVORITES ♡ — food, drink, song, quote, detail
A38: Names, conversations, inside jokes, strangers you met, or the person who made the day. | H38: Favorite meal, drink, place, song, outfit, purchase, phrase, view — the little stuff.
A44: NEXT-TIME NOTES ✦ — what would I do differently? | H44: WOULD I DO IT AGAIN? ♡ — absolutely, maybe, or once was enough?
A45: Book earlier? Stay longer? Bring something? Skip something? Give future-you the cheat sheet. | H45: Why or why not — and who would you bring if you did it again?
A51: TINY DETAILS I DON’T WANT TO FORGET ✦
A52: The tiny thing future-you would never think to write down later: a phrase, receipt, weather, song, snack, outfit, number, joke…
A59: PHOTO / KEEPSAKE / LINK ♡ — drop a memory here | H59: NOTE TO FUTURE ME ✦ — what do I want to remember about this version of me?
A60: Paste a photo link, album, ticket, map, playlist, receipt, reservation, or keepsake note here. | H60: What do you want future-you to remember about who you were in this moment?
A66: NEXT TIME… ✦ — where does this memory make me want to go or what do I want to try next?

Sheet STICKER JOURNAL
A1: Sticker Vibe ♡
A3: Collect it, catalog it, paste it somewhere cute.
A4: Dashboard Add-On ✦ Track your sticker collection on the left, then scroll down for your digital sticker board.
A6: LOGGED | C6: UNUSED | E6: USED | G6: FAVORITES | I6: TOTAL SPENT | K6: DUPLICATES
A7: =COUNTA($A$13:$A$250) -> 0 | C7: =COUNTIF($H$12:$H$250,"Unused") -> 0 | E7: =COUNTIF($H$12:$H$250,"Used") -> 0 | G7: =COUNTIF($K$12:$K$250,TRUE) -> 0 | I7: =SUM($E$12:$E$250) -> 0 | K7: =SUM($J$12:$J$250) -> 0
A12: STICKER | B12: THEME | C12: SOURCE / SHOP | D12: ACQUIRED | E12: COST | F12: COLOR | G12: STYLE | H12: STATUS | I12: USED ON | J12: DUPLICATES | K12: FAVORITE | L12: NOTES / LINK
K13: FALSE
K14: FALSE
K15: FALSE
K16: FALSE
K17: FALSE
K18: FALSE
K19: FALSE
K20: FALSE
K21: FALSE
K22: FALSE
K23: FALSE
K24: FALSE
K25: FALSE
K26: FALSE | N26: DIGITAL STICKER BOARD ♡
K27: FALSE | N27: Paste images, emojis, screenshots, or little digital stickers into the spaces below. Make it messy, cute, themed, or completely chaotic. ✦
K28: FALSE
K29: FALSE
K30: FALSE
K31: FALSE
K32: FALSE
K33: FALSE
K34: FALSE
K35: FALSE
K36: FALSE
K37: FALSE
K38: FALSE
K39: FALSE
... K50: FALSE
K51: FALSE | N51: BOARD NOTES ✦
K52: FALSE | N52: Sticker-swap ideas, favorite shops, where you want to use one, collection themes, or whatever belongs with your board.
K53: FALSE
K54: FALSE
K55: FALSE
K56: FALSE
...

Sheet MOVIE + TV
A1: Screen Vibe ♡
A3: For everything you’re watching, waiting on, loving, or abandoning halfway through.
A4: Dashboard Add-On ✦ Start with one page. If your reviews need more room later, Screen Discussion can become the companion sheet.
A6: FINISHED | C6: WATCHING | E6: WATCHLIST | G6: FAVORITES | I6: AVG RATING | K6: MOVIES | M6: SERIES
A7: =COUNTIF($D$14:$D$250,"Finished") -> 0 | C7: =COUNTIF($D$14:$D$250,"Watching") -> 0 | E7: =COUNTIF($D$14:$D$250,"Watchlist") -> 0 | G7: =COUNTIF($L$14:$L$250,TRUE) -> 0 | I7: =IFERROR(AVERAGEIF($D$14:$D$250,"Finished",$H$14:$H$250),"") | K7: =COUNTIF($B$14:$B$250,"Movie") -> 0 | M7: =COUNTIF($B$14:$B$250,"Series") -> 0
A9: CURRENTLY WATCHING ♡ | H9: UP NEXT ✦
A10: {=IFERROR(INDEX($A$14:$A$250,MATCH("Watching",$D$14:$D$250,0))&CHAR(10)&INDEX($E$14:$E$250,MATCH("Watching",$D$14:$D$250,0)),"Add something you’re watching ♡")} -> Add something you’re watching ♡ | H10: {=IFERROR(INDEX($A$14:$A$250,MATCH("Watchlist",$D$14:$D$250,0)),"Add something to your watchlist ✦")} -> Add something to your watchlist ✦
A13: TITLE | B13: TYPE | C13: GENRE | D13: STATUS | E13: PLATFORM | F13: SEASON | G13: EPISODE | H13: RATING | I13: START DATE | J13: FINISH DATE | K13: WATCHED WITH | L13: FAVORITE | M13: REWATCH? | N13: NOTES / MINI REVIEW
L14: FALSE | M14: FALSE
L15: FALSE | M15: FALSE
L16: FALSE | M16: FALSE
L17: FALSE | M17: FALSE
L18: FALSE | M18: FALSE
L19: FALSE | M19: FALSE
L20: FALSE | M20: FALSE
L21: FALSE | M21: FALSE
L22: FALSE | M22: FALSE
L23: FALSE | M23: FALSE
L24: FALSE | M24: FALSE
L25: FALSE | M25: FALSE
... L250: FALSE | M250: FALSE

Sheet TRAVEL PLANNER
A1: Travel Vibe ♡
A3: Dream it, book it, pack for it, then actually enjoy it.
A4: Dashboard Add-On ✦ Travel Vibe keeps the master trip list; Trip Details and Packing List are the luxe companion pages.
A6: UPCOMING | C6: BOOKED | E6: COMPLETED | G6: TOTAL BUDGET | I6: TOTAL SPENT | K6: DAYS TO NEXT
A7: =COUNTIFS($D$14:$D$250,">="&TODAY(),$C$14:$C$250,"<>Cancelled") -> 0 | C7: =COUNTIF($C$14:$C$250,"Booked") -> 0 | E7: =COUNTIF($C$14:$C$250,"Completed") -> 0 | G7: =SUM($G$14:$G$250) -> 0 | I7: =SUM($H$14:$H$250) -> 0 | K7: =IFERROR(__xludf.DUMMYFUNCTION("IFERROR(MIN(FILTER($D$14:$D$250,$D$14:$D$250>=TODAY(),$C$14:$C$250<>""Cancelled""))-TODAY(),"""")"),"")
A9: NEXT TRIP ♡ | G9: MOST RECENT TRIP ✦
A10: =IFERROR(__xludf.DUMMYFUNCTION("IFERROR(INDEX(SORT(FILTER({$D$14:$D$250,$A$14:$A$250,$B$14:$B$250},$D$14:$D$250>=TODAY(),$C$14:$C$250<>""Cancelled""),1,TRUE),1,2)&CHAR(10)&INDEX(SORT(FILTER({$D$14:$D$250,$A$14:$A$250,$B$14:$B$250},$D$14:$D$250>=TODAY(),$C$14:$C$250<>""Cancelled""),1,TRU"&"E),1,3),""Add a trip you’re dreaming about ♡"")"),"Add a trip you’re dreaming about ♡") -> Add a trip you’re dreaming about ♡ | G10: =IFERROR(__xludf.DUMMYFUNCTION("IFERROR(INDEX(SORT(FILTER({$E$14:$E$250,$A$14:$A$250,$B$14:$B$250},$C$14:$C$250=""Completed"",$E$14:$E$250<>""""),1,FALSE),1,2)&CHAR(10)&INDEX(SORT(FILTER({$E$14:$E$250,$A$14:$A$250,$B$14:$B$250},$C$14:$C$250=""Completed"",$E$14:$E$250<>""""),1,FALSE),1,3"&"),""Your completed trips will live here ✦"")"),"Your completed trips will live here ✦") -> Your completed trips will live here ✦
A13: TRIP NAME | B13: DESTINATION | C13: STATUS | D13: START DATE | E13: END DATE | F13: TRAVELERS | G13: EST. BUDGET | H13: ACTUAL SPENT | I13: TRANSPORTATION | J13: LODGING | K13: CONFIRMATION / LINK | L13: NOTES

Sheet TRIP DETAILS
A1: Trip Details ♡
A3: The actual plan — without squeezing a whole vacation into one tiny box.
A4: Choose a trip from Travel Vibe. Duplicate this page for each trip you want to plan in detail. ✦
A6: TRIP | G6: DESTINATION | H6: {=IFERROR(INDEX('TRAVEL PLANNER'!$B$14:$B$250,MATCH($B$6,'TRAVEL PLANNER'!$A$14:$A$250,0)),"")}
A7: DATES | B7: {=IFERROR(TEXT(INDEX('TRAVEL PLANNER'!$D$14:$D$250,MATCH($B$6,'TRAVEL PLANNER'!$A$14:$A$250,0)),"mmm d")&" – "&TEXT(INDEX('TRAVEL PLANNER'!$E$14:$E$250,MATCH($B$6,'TRAVEL PLANNER'!$A$14:$A$250,0)),"mmm d, yyyy"),"")} | G7: TRAVELERS | H7: {=IFERROR(INDEX('TRAVEL PLANNER'!$F$14:$F$250,MATCH($B$6,'TRAVEL PLANNER'!$A$14:$A$250,0)),"")}
A9: TRIP VIBE / GOAL ♡ | H9: STAY + TRANSPORT ✦
H10: {=IFERROR("Stay: "&INDEX('TRAVEL PLANNER'!$J$14:$J$250,MATCH($B$6,'TRAVEL PLANNER'!$A$14:$A$250,0)),"")}
H11: {=IFERROR("Transport: "&INDEX('TRAVEL PLANNER'!$I$14:$I$250,MATCH($B$6,'TRAVEL PLANNER'!$A$14:$A$250,0)),"")}
H12: {=IFERROR("Budget: "&TEXT(INDEX('TRAVEL PLANNER'!$G$14:$G$250,MATCH($B$6,'TRAVEL PLANNER'!$A$14:$A$250,0)),"$#,##0"),"")}
A15: MUST DO ♡
A16: ACTIVITY / PLACE | F16: PRIORITY | H16: BOOKED? | I16: NOTES
H17: FALSE
H18: FALSE
H19: FALSE
H20: FALSE
H21: FALSE
H22: FALSE
H23: FALSE
H24: FALSE
A26: FOOD + RESTAURANTS ✦
A27: PLACE | F27: TYPE | H27: PRIORITY | J27: RESERVED? | K27: NOTES
J28: FALSE
J29: FALSE
J30: FALSE
J31: FALSE
J32: FALSE
J33: FALSE
J34: FALSE
J35: FALSE
A37: DAY-BY-DAY ITINERARY ♡
A38: DATE | C38: TIME | E38: PLAN | I38: LOCATION | L38: COST | N38: DONE?
N39: FALSE
N40: FALSE
N41: FALSE
N42: FALSE
N43: FALSE
N44: FALSE
N45: FALSE
N46: FALSE
N47: FALSE
...

Sheet PACKING LIST
A1: Packing Vibe ♡
A3: A real checklist you can actually check — plus room for the weird little things only you need.
A4: Choose a trip, work through the preset list, then use the Custom rows for anything you refuse to forget. Uncheck the boxes to reset for your next trip. ✦
A6: TRIP | E6: PACKED | F6: =COUNTIF($C$11:$C$80,TRUE) -> 0 | G6: TOTAL | H6: =COUNTA($B$11:$B$80) -> 55
A7: PROGRESS | C7: =IFERROR(__xludf.DUMMYFUNCTION("IFERROR(SPARKLINE($F$6/$H$6,{""charttype"",""bar"";""max"",1;""color1"",""#D5AE5E""}),"""")"),"")
A9: PACKING CHECKLIST ✦
A10: CATEGORY | B10: ITEM | C10: PACKED? | D10: BAG | E10: QTY | F10: NOTES
A11: Essentials | B11: Wallet / cards / cash | C11: FALSE
A12: Essentials | B12: Keys | C12: FALSE
A13: Essentials | B13: Medications | C13: FALSE
A14: Essentials | B14: Reusable water bottle | C14: FALSE
A15: Documents | B15: ID / passport | C15: FALSE
A16: Documents | B16: Tickets / boarding passes | C16: FALSE
A17: Documents | B17: Reservations / confirmations | C17: FALSE
A18: Documents | B18: Insurance / emergency info | C18: FALSE
A19: Tech | B19: Phone | C19: FALSE
A20: Tech | B20: Phone charger | C20: FALSE
A21: Tech | B21: Power bank | C21: FALSE
A22: Tech | B22: Headphones / earbuds | C22: FALSE
... A51: Destination | B51: Activity-specific gear | C51: FALSE
A52: Custom | C52: FALSE
A53: Custom | C53: FALSE
A54: Custom | C54: FALSE
A55: Custom | C55: FALSE
A56: Custom | C56: FALSE
A57: Custom | C57: FALSE
A58: Custom | C58: FALSE
A59: Custom | C59: FALSE
A60: Custom | C60: FALSE
A61: Custom | C61: FALSE
A62: Custom | C62: FALSE
A63: Custom | C63: FALSE
... A65: Custom | C65: FALSE
C66: FALSE
C67: FALSE
C68: FALSE
C69: FALSE
C70: FALSE
C71: FALSE
C72: FALSE
...

Sheet GIFT + WISHLIST
A1: Gift + Wishlist Vibe ♡
A3: For remembering the people you love — and the things you keep sending yourself links to.
A4: Dashboard Add-On ✦ Keep gifts-to-give and wishlists together without turning either one into a chaotic note in your phone.
A6: UPCOMING GIFTS | C6: GIFT BUDGET | E6: GIFT SPENT | G6: STILL TO BUY | I6: WISHLIST ITEMS | K6: WISHLIST TOTAL
A7: =COUNTIFS($C$13:$C$30,">="&TODAY(),$C$13:$C$30,"<="&TODAY()+30,$I$13:$I$30,FALSE) -> 0 | C7: =SUM($E$13:$E$30) -> 0 | E7: =SUM($F$13:$F$30) -> 0 | G7: =COUNTIFS($D$13:$D$30,"<>",$G$13:$G$30,FALSE) -> 0 | I7: =COUNTA($A$36:$A$60) -> 0 | K7: =SUM($E$36:$E$60) -> 0
A9: GIFTS TO GIVE ♡
A10: Plan it, buy it, wrap it, give it — no last-minute panic required. ✦
A12: RECIPIENT | B12: OCCASION | C12: DATE | D12: GIFT IDEA | E12: BUDGET | F12: ACTUAL | G12: PURCHASED? | H12: WRAPPED? | I12: GIVEN? | J12: STORE / LINK | K12: PRIORITY | L12: NOTES
G13: FALSE | H13: FALSE | I13: FALSE
G14: FALSE | H14: FALSE | I14: FALSE
G15: FALSE | H15: FALSE | I15: FALSE
G16: FALSE | H16: FALSE | I16: FALSE
G17: FALSE | H17: FALSE | I17: FALSE
G18: FALSE | H18: FALSE | I18: FALSE
G19: FALSE | H19: FALSE | I19: FALSE
G20: FALSE | H20: FALSE | I20: FALSE
G21: FALSE | H21: FALSE | I21: FALSE
G22: FALSE | H22: FALSE | I22: FALSE
G23: FALSE | H23: FALSE | I23: FALSE
G24: FALSE | H24: FALSE | I24: FALSE
... G30: FALSE | H30: FALSE | I30: FALSE
A32: MY WISHLIST ✦
A33: Save the pretty, practical, ridiculous, and someday-maybe things in one place.
A35: ITEM | B35: FOR | C35: CATEGORY | D35: PRIORITY | E35: EST. PRICE | F35: STORE / LINK | G35: RECEIVED? | H35: BOUGHT MYSELF? | I35: ADDED DATE | J35: FAVORITE? | K35: NEED BY | L35: NOTES
G36: FALSE | H36: FALSE | J36: FALSE
G37: FALSE | H37: FALSE | J37: FALSE
G38: FALSE | H38: FALSE | J38: FALSE
G39: FALSE | H39: FALSE | J39: FALSE
G40: FALSE | H40: FALSE | J40: FALSE
G41: FALSE | H41: FALSE | J41: FALSE
G42: FALSE | H42: FALSE | J42: FALSE
G43: FALSE | H43: FALSE | J43: FALSE
G44: FALSE | H44: FALSE | J44: FALSE
G45: FALSE | H45: FALSE | J45: FALSE
G46: FALSE | H46: FALSE | J46: FALSE
G47: FALSE | H47: FALSE | J47: FALSE
... G60: FALSE | H60: FALSE | J60: FALSE
