Workbook

Sheet START HERE
A1: The Vibe Dashboard ✦
A3: Your whole life, one workbook. Welcome to the STV Smart Excel System.
A5: START HERE ♡
A6: This workbook is designed to be used from the Dashboard out. Enter your information in the working tabs; the Dashboard pulls the important pieces back to you. White cells are for typing. Cream/soft-gold cells are calculated or guided. Burgundy headers are the STV anchors.
A12: THE 5-MINUTE SETUP
A13: 1 | B13: SETTINGS | D13: Customize your dropdowns and categories.
A14: 2 | B14: TASKS | D14: Dump everything you are carrying mentally.
A15: 3 | B15: MONEY + CALENDAR | D15: Add bills, transactions, appointments, and events.
A16: 4 | B16: GOALS | D16: Add the things you are actively working toward.
A17: 5 | B17: DASHBOARD | D17: Come back here for the snapshot that matters.
A21: STV RULE OF THUMB ✦
A22: Do not delete the shaded helper/formula columns unless you know exactly what they do. They are the quiet little engine behind the Dashboard. Add your life to the white cells — let the formulas do the rest.

Sheet DASHBOARD
A1: The Vibe Dashboard ✦
A3: Your whole life, one workbook. Cute enough to open. Smart enough to run it.
B5: SHE'S THE VIBE • SMART LIFE SYSTEM | H5: =TODAY() -> 46288
B7: OPEN TASKS | E7: DUE THIS WEEK | H7: BILLS COMING | K7: MONTHLY NET
B8: =COUNTIFS(TASKS!$A$6:$A$205,"<>",TASKS!$F$6:$F$205,"<>Done") -> 5 | E8: =COUNTIFS(TASKS!$A$6:$A$205,"<>",TASKS!$E$6:$E$205,">="&TODAY(),TASKS!$E$6:$E$205,"<="&TODAY()+7,TASKS!$F$6:$F$205,"<>Done") -> 0 | H8: =COUNTIFS(MONEY!$I$9:$I$208,"<>",MONEY!$J$9:$J$208,">="&TODAY(),MONEY!$J$9:$J$208,"<="&TODAY()+14,MONEY!$M$9:$M$208,"<>Paid") -> 2 | K8: =SUMIFS(MONEY!$E$14:$E$213,MONEY!$C$14:$C$213,"Income",MONEY!$A$14:$A$213,">="&EOMONTH(TODAY(),-1)+1,MONEY!$A$14:$A$213,"<="&EOMONTH(TODAY(),0))-SUMIFS(MONEY!$E$14:$E$213,MONEY!$C$14:$C$213,"Expense",MONEY!$A$14:$A$213,">="&EOMONTH(TODAY(),-1)+1,MONEY!$A$14:$A$213,"<="&EOMONTH(TODAY(),0)) -> 2547.39
B13: TODAY'S PRIORITIES ♡ | H13: UPCOMING BILLS ✦
B14: Task | C14: Area | D14: Due | E14: Priority | F14: Status | H14: Bill | I14: Due | J14: Amount | K14: Type | L14: Status
B15: {=IF(SMALL(TASKS!$H$6:$H$205,1)>=999999,"",INDEX(TASKS!$A$6:$A$205,MATCH(SMALL(TASKS!$H$6:$H$205,1),TASKS!$H$6:$H$205,0)))} -> Pay electric bill | C15: {=IF(B15="","",INDEX(TASKS!$B$6:$B$205,MATCH(B15,TASKS!$A$6:$A$205,0)))} -> Money | D15: {=IF(B15="","",INDEX(TASKS!$E$6:$E$205,MATCH(B15,TASKS!$A$6:$A$205,0)))} -> 46281 | E15: {=IF(B15="","",INDEX(TASKS!$C$6:$C$205,MATCH(B15,TASKS!$A$6:$A$205,0)))} -> Urgent | F15: {=IF(B15="","",INDEX(TASKS!$F$6:$F$205,MATCH(B15,TASKS!$A$6:$A$205,0)))} -> Not Started | H15: {=IF(SMALL(MONEY!$P$9:$P$208,1)>=999999,"",INDEX(MONEY!$I$9:$I$208,MATCH(SMALL(MONEY!$P$9:$P$208,1),MONEY!$P$9:$P$208,0)))} -> Car Insurance | I15: {=IF(H15="","",INDEX(MONEY!$J$9:$J$208,MATCH(H15,MONEY!$I$9:$I$208,0)))} -> 46291 | J15: {=IF(H15="","",INDEX(MONEY!$L$9:$L$208,MATCH(H15,MONEY!$I$9:$I$208,0)))} -> 210 | K15: {=IF(H15="","",INDEX(MONEY!$K$9:$K$208,MATCH(H15,MONEY!$I$9:$I$208,0)))} -> Bill | L15: {=IF(H15="","",INDEX(MONEY!$M$9:$M$208,MATCH(H15,MONEY!$I$9:$I$208,0)))} -> Upcoming
B16: {=IF(SMALL(TASKS!$H$6:$H$205,2)>=999999,"",INDEX(TASKS!$A$6:$A$205,MATCH(SMALL(TASKS!$H$6:$H$205,2),TASKS!$H$6:$H$205,0)))} -> Plan meals for the week | C16: {=IF(B16="","",INDEX(TASKS!$B$6:$B$205,MATCH(B16,TASKS!$A$6:$A$205,0)))} -> Home | D16: {=IF(B16="","",INDEX(TASKS!$E$6:$E$205,MATCH(B16,TASKS!$A$6:$A$205,0)))} -> 46279 | E16: {=IF(B16="","",INDEX(TASKS!$C$6:$C$205,MATCH(B16,TASKS!$A$6:$A$205,0)))} -> High | F16: {=IF(B16="","",INDEX(TASKS!$F$6:$F$205,MATCH(B16,TASKS!$A$6:$A$205,0)))} -> Not Started | H16: {=IF(SMALL(MONEY!$P$9:$P$208,2)>=999999,"",INDEX(MONEY!$I$9:$I$208,MATCH(SMALL(MONEY!$P$9:$P$208,2),MONEY!$P$9:$P$208,0)))} -> Music | I16: {=IF(H16="","",INDEX(MONEY!$J$9:$J$208,MATCH(H16,MONEY!$I$9:$I$208,0)))} -> 46293 | J16: {=IF(H16="","",INDEX(MONEY!$L$9:$L$208,MATCH(H16,MONEY!$I$9:$I$208,0)))} -> 10.99 | K16: {=IF(H16="","",INDEX(MONEY!$K$9:$K$208,MATCH(H16,MONEY!$I$9:$I$208,0)))} -> Subscription | L16: {=IF(H16="","",INDEX(MONEY!$M$9:$M$208,MATCH(H16,MONEY!$I$9:$I$208,0)))} -> Upcoming
B17: {=IF(SMALL(TASKS!$H$6:$H$205,3)>=999999,"",INDEX(TASKS!$A$6:$A$205,MATCH(SMALL(TASKS!$H$6:$H$205,3),TASKS!$H$6:$H$205,0)))} -> Grocery shopping | C17: {=IF(B17="","",INDEX(TASKS!$B$6:$B$205,MATCH(B17,TASKS!$A$6:$A$205,0)))} -> Home | D17: {=IF(B17="","",INDEX(TASKS!$E$6:$E$205,MATCH(B17,TASKS!$A$6:$A$205,0)))} -> 46283 | E17: {=IF(B17="","",INDEX(TASKS!$C$6:$C$205,MATCH(B17,TASKS!$A$6:$A$205,0)))} -> High | F17: {=IF(B17="","",INDEX(TASKS!$F$6:$F$205,MATCH(B17,TASKS!$A$6:$A$205,0)))} -> Not Started | H17: {=IF(SMALL(MONEY!$P$9:$P$208,3)>=999999,"",INDEX(MONEY!$I$9:$I$208,MATCH(SMALL(MONEY!$P$9:$P$208,3),MONEY!$P$9:$P$208,0)))} | I17: {=IF(H17="","",INDEX(MONEY!$J$9:$J$208,MATCH(H17,MONEY!$I$9:$I$208,0)))} | J17: {=IF(H17="","",INDEX(MONEY!$L$9:$L$208,MATCH(H17,MONEY!$I$9:$I$208,0)))} | K17: {=IF(H17="","",INDEX(MONEY!$K$9:$K$208,MATCH(H17,MONEY!$I$9:$I$208,0)))} | L17: {=IF(H17="","",INDEX(MONEY!$M$9:$M$208,MATCH(H17,MONEY!$I$9:$I$208,0)))}
B18: {=IF(SMALL(TASKS!$H$6:$H$205,4)>=999999,"",INDEX(TASKS!$A$6:$A$205,MATCH(SMALL(TASKS!$H$6:$H$205,4),TASKS!$H$6:$H$205,0)))} -> Workout 30 minutes | C18: {=IF(B18="","",INDEX(TASKS!$B$6:$B$205,MATCH(B18,TASKS!$A$6:$A$205,0)))} -> Health | D18: {=IF(B18="","",INDEX(TASKS!$E$6:$E$205,MATCH(B18,TASKS!$A$6:$A$205,0)))} -> 46280 | E18: {=IF(B18="","",INDEX(TASKS!$C$6:$C$205,MATCH(B18,TASKS!$A$6:$A$205,0)))} -> Medium | F18: {=IF(B18="","",INDEX(TASKS!$F$6:$F$205,MATCH(B18,TASKS!$A$6:$A$205,0)))} -> In Progress | H18: {=IF(SMALL(MONEY!$P$9:$P$208,4)>=999999,"",INDEX(MONEY!$I$9:$I$208,MATCH(SMALL(MONEY!$P$9:$P$208,4),MONEY!$P$9:$P$208,0)))} | I18: {=IF(H18="","",INDEX(MONEY!$J$9:$J$208,MATCH(H18,MONEY!$I$9:$I$208,0)))} | J18: {=IF(H18="","",INDEX(MONEY!$L$9:$L$208,MATCH(H18,MONEY!$I$9:$I$208,0)))} | K18: {=IF(H18="","",INDEX(MONEY!$K$9:$K$208,MATCH(H18,MONEY!$I$9:$I$208,0)))} | L18: {=IF(H18="","",INDEX(MONEY!$M$9:$M$208,MATCH(H18,MONEY!$I$9:$I$208,0)))}
B19: {=IF(SMALL(TASKS!$H$6:$H$205,5)>=999999,"",INDEX(TASKS!$A$6:$A$205,MATCH(SMALL(TASKS!$H$6:$H$205,5),TASKS!$H$6:$H$205,0)))} -> Organize bedroom | C19: {=IF(B19="","",INDEX(TASKS!$B$6:$B$205,MATCH(B19,TASKS!$A$6:$A$205,0)))} -> Home | D19: {=IF(B19="","",INDEX(TASKS!$E$6:$E$205,MATCH(B19,TASKS!$A$6:$A$205,0)))} -> 46282 | E19: {=IF(B19="","",INDEX(TASKS!$C$6:$C$205,MATCH(B19,TASKS!$A$6:$A$205,0)))} -> Low | F19: {=IF(B19="","",INDEX(TASKS!$F$6:$F$205,MATCH(B19,TASKS!$A$6:$A$205,0)))} -> Not Started | H19: {=IF(SMALL(MONEY!$P$9:$P$208,5)>=999999,"",INDEX(MONEY!$I$9:$I$208,MATCH(SMALL(MONEY!$P$9:$P$208,5),MONEY!$P$9:$P$208,0)))} | I19: {=IF(H19="","",INDEX(MONEY!$J$9:$J$208,MATCH(H19,MONEY!$I$9:$I$208,0)))} | J19: {=IF(H19="","",INDEX(MONEY!$L$9:$L$208,MATCH(H19,MONEY!$I$9:$I$208,0)))} | K19: {=IF(H19="","",INDEX(MONEY!$K$9:$K$208,MATCH(H19,MONEY!$I$9:$I$208,0)))} | L19: {=IF(H19="","",INDEX(MONEY!$M$9:$M$208,MATCH(H19,MONEY!$I$9:$I$208,0)))}
B22: NEXT APPOINTMENTS + EVENTS ♡ | H22: SAVINGS PROGRESS ✦
B23: Person / Area | C23: Event | D23: Date | E23: Time | F23: Type | H23: CURRENT | I23: TARGET
B24: {=IF(SMALL(CALENDAR!$P$9:$P$208,1)>=999999,"",INDEX(CALENDAR!$J$9:$J$208,MATCH(SMALL(CALENDAR!$P$9:$P$208,1),CALENDAR!$P$9:$P$208,0)))} -> School | C24: {=IF(B24="","",INDEX(CALENDAR!$K$9:$K$208,MATCH(SMALL(CALENDAR!$P$9:$P$208,1),CALENDAR!$P$9:$P$208,0)))} -> Picture Day | D24: {=IF(B24="","",INDEX(CALENDAR!$L$9:$L$208,MATCH(SMALL(CALENDAR!$P$9:$P$208,1),CALENDAR!$P$9:$P$208,0)))} -> 46289 | E24: {=IF(B24="","",INDEX(CALENDAR!$M$9:$M$208,MATCH(SMALL(CALENDAR!$P$9:$P$208,1),CALENDAR!$P$9:$P$208,0)))} -> 8:00 AM | F24: {=IF(B24="","",INDEX(CALENDAR!$N$9:$N$208,MATCH(SMALL(CALENDAR!$P$9:$P$208,1),CALENDAR!$P$9:$P$208,0)))} -> School | H24: =SUM(MONEY!$K$214:$K$238) -> 4150 | I24: =SUM(MONEY!$J$214:$J$238) -> 13500
B25: {=IF(SMALL(CALENDAR!$P$9:$P$208,2)>=999999,"",INDEX(CALENDAR!$J$9:$J$208,MATCH(SMALL(CALENDAR!$P$9:$P$208,2),CALENDAR!$P$9:$P$208,0)))} -> Me | C25: {=IF(B25="","",INDEX(CALENDAR!$K$9:$K$208,MATCH(SMALL(CALENDAR!$P$9:$P$208,2),CALENDAR!$P$9:$P$208,0)))} -> Monthly Reset | D25: {=IF(B25="","",INDEX(CALENDAR!$L$9:$L$208,MATCH(SMALL(CALENDAR!$P$9:$P$208,2),CALENDAR!$P$9:$P$208,0)))} -> 46296 | E25: {=IF(B25="","",INDEX(CALENDAR!$M$9:$M$208,MATCH(SMALL(CALENDAR!$P$9:$P$208,2),CALENDAR!$P$9:$P$208,0)))} -> 7:00 PM | F25: {=IF(B25="","",INDEX(CALENDAR!$N$9:$N$208,MATCH(SMALL(CALENDAR!$P$9:$P$208,2),CALENDAR!$P$9:$P$208,0)))} -> Personal
B26: {=IF(SMALL(CALENDAR!$P$9:$P$208,3)>=999999,"",INDEX(CALENDAR!$J$9:$J$208,MATCH(SMALL(CALENDAR!$P$9:$P$208,3),CALENDAR!$P$9:$P$208,0)))} | C26: {=IF(B26="","",INDEX(CALENDAR!$K$9:$K$208,MATCH(SMALL(CALENDAR!$P$9:$P$208,3),CALENDAR!$P$9:$P$208,0)))} | D26: {=IF(B26="","",INDEX(CALENDAR!$L$9:$L$208,MATCH(SMALL(CALENDAR!$P$9:$P$208,3),CALENDAR!$P$9:$P$208,0)))} | E26: {=IF(B26="","",INDEX(CALENDAR!$M$9:$M$208,MATCH(SMALL(CALENDAR!$P$9:$P$208,3),CALENDAR!$P$9:$P$208,0)))} | F26: {=IF(B26="","",INDEX(CALENDAR!$N$9:$N$208,MATCH(SMALL(CALENDAR!$P$9:$P$208,3),CALENDAR!$P$9:$P$208,0)))} | H26: =IFERROR(SUM(MONEY!$K$214:$K$238)/SUM(MONEY!$J$214:$J$238),0) -> 0.30740741
B27: {=IF(SMALL(CALENDAR!$P$9:$P$208,4)>=999999,"",INDEX(CALENDAR!$J$9:$J$208,MATCH(SMALL(CALENDAR!$P$9:$P$208,4),CALENDAR!$P$9:$P$208,0)))} | C27: {=IF(B27="","",INDEX(CALENDAR!$K$9:$K$208,MATCH(SMALL(CALENDAR!$P$9:$P$208,4),CALENDAR!$P$9:$P$208,0)))} | D27: {=IF(B27="","",INDEX(CALENDAR!$L$9:$L$208,MATCH(SMALL(CALENDAR!$P$9:$P$208,4),CALENDAR!$P$9:$P$208,0)))} | E27: {=IF(B27="","",INDEX(CALENDAR!$M$9:$M$208,MATCH(SMALL(CALENDAR!$P$9:$P$208,4),CALENDAR!$P$9:$P$208,0)))} | F27: {=IF(B27="","",INDEX(CALENDAR!$N$9:$N$208,MATCH(SMALL(CALENDAR!$P$9:$P$208,4),CALENDAR!$P$9:$P$208,0)))}
B28: {=IF(SMALL(CALENDAR!$P$9:$P$208,5)>=999999,"",INDEX(CALENDAR!$J$9:$J$208,MATCH(SMALL(CALENDAR!$P$9:$P$208,5),CALENDAR!$P$9:$P$208,0)))} | C28: {=IF(B28="","",INDEX(CALENDAR!$K$9:$K$208,MATCH(SMALL(CALENDAR!$P$9:$P$208,5),CALENDAR!$P$9:$P$208,0)))} | D28: {=IF(B28="","",INDEX(CALENDAR!$L$9:$L$208,MATCH(SMALL(CALENDAR!$P$9:$P$208,5),CALENDAR!$P$9:$P$208,0)))} | E28: {=IF(B28="","",INDEX(CALENDAR!$M$9:$M$208,MATCH(SMALL(CALENDAR!$P$9:$P$208,5),CALENDAR!$P$9:$P$208,0)))} | F28: {=IF(B28="","",INDEX(CALENDAR!$N$9:$N$208,MATCH(SMALL(CALENDAR!$P$9:$P$208,5),CALENDAR!$P$9:$P$208,0)))} | H28: ✦ building the soft life, one transfer at a time ✦
B31: ACTIVE GOALS ✦ | H31: QUICK LINKS ♡
B32: Goal | C32: Area | D32: Target | E32: Progress | F32: Next Action | H32: CALENDAR › | J32: WEEKLY › | L32: TASKS › | N32: MONEY ›
B33: {=IF(SMALL(GOALS!$I$6:$I$105,1)>=999999,"",INDEX(GOALS!$A$6:$A$105,MATCH(SMALL(GOALS!$I$6:$I$105,1),GOALS!$I$6:$I$105,0)))} -> Create a calmer home routine | C33: {=IF(B33="","",INDEX(GOALS!$B$6:$B$105,MATCH(B33,GOALS!$A$6:$A$105,0)))} -> Home | D33: {=IF(B33="","",INDEX(GOALS!$D$6:$D$105,MATCH(B33,GOALS!$A$6:$A$105,0)))} -> 46387 | E33: {=IF(B33="","",INDEX(GOALS!$E$6:$E$105,MATCH(B33,GOALS!$A$6:$A$105,0)))} -> 0.45 | F33: {=IF(B33="","",INDEX(GOALS!$H$6:$H$105,MATCH(B33,GOALS!$A$6:$A$105,0)))} -> Test Sunday reset
B34: {=IF(SMALL(GOALS!$I$6:$I$105,2)>=999999,"",INDEX(GOALS!$A$6:$A$105,MATCH(SMALL(GOALS!$I$6:$I$105,2),GOALS!$I$6:$I$105,0)))} -> Read 12 books | C34: {=IF(B34="","",INDEX(GOALS!$B$6:$B$105,MATCH(B34,GOALS!$A$6:$A$105,0)))} -> Personal | D34: {=IF(B34="","",INDEX(GOALS!$D$6:$D$105,MATCH(B34,GOALS!$A$6:$A$105,0)))} -> 46387 | E34: {=IF(B34="","",INDEX(GOALS!$E$6:$E$105,MATCH(B34,GOALS!$A$6:$A$105,0)))} -> 0.5 | F34: {=IF(B34="","",INDEX(GOALS!$H$6:$H$105,MATCH(B34,GOALS!$A$6:$A$105,0)))} -> Choose next title | H34: HOME › | J34: FAMILY › | L34: GOALS › | N34: SETTINGS ›
B35: {=IF(SMALL(GOALS!$I$6:$I$105,3)>=999999,"",INDEX(GOALS!$A$6:$A$105,MATCH(SMALL(GOALS!$I$6:$I$105,3),GOALS!$I$6:$I$105,0)))} -> Build emergency fund | C35: {=IF(B35="","",INDEX(GOALS!$B$6:$B$105,MATCH(B35,GOALS!$A$6:$A$105,0)))} -> Money | D35: {=IF(B35="","",INDEX(GOALS!$D$6:$D$105,MATCH(B35,GOALS!$A$6:$A$105,0)))} -> 46568 | E35: {=IF(B35="","",INDEX(GOALS!$E$6:$E$105,MATCH(B35,GOALS!$A$6:$A$105,0)))} -> 0.32 | F35: {=IF(B35="","",INDEX(GOALS!$H$6:$H$105,MATCH(B35,GOALS!$A$6:$A$105,0)))} -> Transfer $200
B36: {=IF(SMALL(GOALS!$I$6:$I$105,4)>=999999,"",INDEX(GOALS!$A$6:$A$105,MATCH(SMALL(GOALS!$I$6:$I$105,4),GOALS!$I$6:$I$105,0)))} | C36: {=IF(B36="","",INDEX(GOALS!$B$6:$B$105,MATCH(B36,GOALS!$A$6:$A$105,0)))} | D36: {=IF(B36="","",INDEX(GOALS!$D$6:$D$105,MATCH(B36,GOALS!$A$6:$A$105,0)))} | E36: {=IF(B36="","",INDEX(GOALS!$E$6:$E$105,MATCH(B36,GOALS!$A$6:$A$105,0)))} | F36: {=IF(B36="","",INDEX(GOALS!$H$6:$H$105,MATCH(B36,GOALS!$A$6:$A$105,0)))}

Sheet CALENDAR
A1: Smart Calendar ✦
A3: One calendar for appointments, activities, school, birthdays, and deadlines.
B5: MONTH | C5: 46266 | J5: MASTER EVENT LIST ✦
B7: MON | C7: TUE | D7: WED | E7: THU | F7: FRI | G7: SAT | H7: SUN
B8: =DATE(YEAR($C$5),MONTH($C$5),1)-WEEKDAY(DATE(YEAR($C$5),MONTH($C$5),1),2)+1 -> 46265 | C8: =B8+1 -> 46266 | D8: =C8+1 -> 46267 | E8: =D8+1 -> 46268 | F8: =E8+1 -> 46269 | G8: =F8+1 -> 46270 | H8: =G8+1 -> 46271 | J8: Person / Area | K8: Event | L8: Date | M8: Time | N8: Type | O8: Location / Notes | P8: Days Away
B9: =IFERROR(_xludf.TEXTJOIN(CHAR(10),TRUE,_xlws.FILTER($K$9:$K$208&" • "&$M$9:$M$208,$L$9:$L$208=B8)),"") | C9: =IFERROR(_xludf.TEXTJOIN(CHAR(10),TRUE,_xlws.FILTER($K$9:$K$208&" • "&$M$9:$M$208,$L$9:$L$208=C8)),"") | D9: =IFERROR(_xludf.TEXTJOIN(CHAR(10),TRUE,_xlws.FILTER($K$9:$K$208&" • "&$M$9:$M$208,$L$9:$L$208=D8)),"") | E9: =IFERROR(_xludf.TEXTJOIN(CHAR(10),TRUE,_xlws.FILTER($K$9:$K$208&" • "&$M$9:$M$208,$L$9:$L$208=E8)),"") | F9: =IFERROR(_xludf.TEXTJOIN(CHAR(10),TRUE,_xlws.FILTER($K$9:$K$208&" • "&$M$9:$M$208,$L$9:$L$208=F8)),"") | G9: =IFERROR(_xludf.TEXTJOIN(CHAR(10),TRUE,_xlws.FILTER($K$9:$K$208&" • "&$M$9:$M$208,$L$9:$L$208=G8)),"") | H9: =IFERROR(_xludf.TEXTJOIN(CHAR(10),TRUE,_xlws.FILTER($K$9:$K$208&" • "&$M$9:$M$208,$L$9:$L$208=H8)),"") | J9: Family | K9: Movie Night | L9: 46283 | M9: 7:00 PM | N9: Activity | O9: Home | P9: =IF(OR(J9="",L9<TODAY()),999999,L9-TODAY()+ROW()/100000) -> 999999
B10: =H8+1 -> 46272 | C10: =B10+1 -> 46273 | D10: =C10+1 -> 46274 | E10: =D10+1 -> 46275 | F10: =E10+1 -> 46276 | G10: =F10+1 -> 46277 | H10: =G10+1 -> 46278 | J10: Alex | K10: Dentist | L10: 46287 | M10: 3:30 PM | N10: Appointment | O10: Dental Office | P10: =IF(OR(J10="",L10<TODAY()),999999,L10-TODAY()+ROW()/100000) -> 999999
B11: =IFERROR(_xludf.TEXTJOIN(CHAR(10),TRUE,_xlws.FILTER($K$9:$K$208&" • "&$M$9:$M$208,$L$9:$L$208=B10)),"") | C11: =IFERROR(_xludf.TEXTJOIN(CHAR(10),TRUE,_xlws.FILTER($K$9:$K$208&" • "&$M$9:$M$208,$L$9:$L$208=C10)),"") | D11: =IFERROR(_xludf.TEXTJOIN(CHAR(10),TRUE,_xlws.FILTER($K$9:$K$208&" • "&$M$9:$M$208,$L$9:$L$208=D10)),"") | E11: =IFERROR(_xludf.TEXTJOIN(CHAR(10),TRUE,_xlws.FILTER($K$9:$K$208&" • "&$M$9:$M$208,$L$9:$L$208=E10)),"") | F11: =IFERROR(_xludf.TEXTJOIN(CHAR(10),TRUE,_xlws.FILTER($K$9:$K$208&" • "&$M$9:$M$208,$L$9:$L$208=F10)),"") | G11: =IFERROR(_xludf.TEXTJOIN(CHAR(10),TRUE,_xlws.FILTER($K$9:$K$208&" • "&$M$9:$M$208,$L$9:$L$208=G10)),"") | H11: =IFERROR(_xludf.TEXTJOIN(CHAR(10),TRUE,_xlws.FILTER($K$9:$K$208&" • "&$M$9:$M$208,$L$9:$L$208=H10)),"") | J11: School | K11: Picture Day | L11: 46289 | M11: 8:00 AM | N11: School | O11: Campus | P11: =IF(OR(J11="",L11<TODAY()),999999,L11-TODAY()+ROW()/100000) -> 1.00011
B12: =H10+1 -> 46279 | C12: =B12+1 -> 46280 | D12: =C12+1 -> 46281 | E12: =D12+1 -> 46282 | F12: =E12+1 -> 46283 | G12: =F12+1 -> 46284 | H12: =G12+1 -> 46285 | J12: Me | K12: Monthly Reset | L12: 46296 | M12: 7:00 PM | N12: Personal | O12: Home | P12: =IF(OR(J12="",L12<TODAY()),999999,L12-TODAY()+ROW()/100000) -> 8.00012
B13: =IFERROR(_xludf.TEXTJOIN(CHAR(10),TRUE,_xlws.FILTER($K$9:$K$208&" • "&$M$9:$M$208,$L$9:$L$208=B12)),"") | C13: =IFERROR(_xludf.TEXTJOIN(CHAR(10),TRUE,_xlws.FILTER($K$9:$K$208&" • "&$M$9:$M$208,$L$9:$L$208=C12)),"") | D13: =IFERROR(_xludf.TEXTJOIN(CHAR(10),TRUE,_xlws.FILTER($K$9:$K$208&" • "&$M$9:$M$208,$L$9:$L$208=D12)),"") | E13: =IFERROR(_xludf.TEXTJOIN(CHAR(10),TRUE,_xlws.FILTER($K$9:$K$208&" • "&$M$9:$M$208,$L$9:$L$208=E12)),"") | F13: =IFERROR(_xludf.TEXTJOIN(CHAR(10),TRUE,_xlws.FILTER($K$9:$K$208&" • "&$M$9:$M$208,$L$9:$L$208=F12)),"") | G13: =IFERROR(_xludf.TEXTJOIN(CHAR(10),TRUE,_xlws.FILTER($K$9:$K$208&" • "&$M$9:$M$208,$L$9:$L$208=G12)),"") | H13: =IFERROR(_xludf.TEXTJOIN(CHAR(10),TRUE,_xlws.FILTER($K$9:$K$208&" • "&$M$9:$M$208,$L$9:$L$208=H12)),"") | J13: jane | P13: =IF(OR(J13="",L13<TODAY()),999999,L13-TODAY()+ROW()/100000) -> 999999
B14: =H12+1 -> 46286 | C14: =B14+1 -> 46287 | D14: =C14+1 -> 46288 | E14: =D14+1 -> 46289 | F14: =E14+1 -> 46290 | G14: =F14+1 -> 46291 | H14: =G14+1 -> 46292 | P14: =IF(OR(J14="",L14<TODAY()),999999,L14-TODAY()+ROW()/100000) -> 999999
B15: =IFERROR(_xludf.TEXTJOIN(CHAR(10),TRUE,_xlws.FILTER($K$9:$K$208&" • "&$M$9:$M$208,$L$9:$L$208=B14)),"") | C15: =IFERROR(_xludf.TEXTJOIN(CHAR(10),TRUE,_xlws.FILTER($K$9:$K$208&" • "&$M$9:$M$208,$L$9:$L$208=C14)),"") | D15: =IFERROR(_xludf.TEXTJOIN(CHAR(10),TRUE,_xlws.FILTER($K$9:$K$208&" • "&$M$9:$M$208,$L$9:$L$208=D14)),"") | E15: =IFERROR(_xludf.TEXTJOIN(CHAR(10),TRUE,_xlws.FILTER($K$9:$K$208&" • "&$M$9:$M$208,$L$9:$L$208=E14)),"") | F15: =IFERROR(_xludf.TEXTJOIN(CHAR(10),TRUE,_xlws.FILTER($K$9:$K$208&" • "&$M$9:$M$208,$L$9:$L$208=F14)),"") | G15: =IFERROR(_xludf.TEXTJOIN(CHAR(10),TRUE,_xlws.FILTER($K$9:$K$208&" • "&$M$9:$M$208,$L$9:$L$208=G14)),"") | H15: =IFERROR(_xludf.TEXTJOIN(CHAR(10),TRUE,_xlws.FILTER($K$9:$K$208&" • "&$M$9:$M$208,$L$9:$L$208=H14)),"") | P15: =IF(OR(J15="",L15<TODAY()),999999,L15-TODAY()+ROW()/100000) -> 999999
B16: =H14+1 -> 46293 | C16: =B16+1 -> 46294 | D16: =C16+1 -> 46295 | E16: =D16+1 -> 46296 | F16: =E16+1 -> 46297 | G16: =F16+1 -> 46298 | H16: =G16+1 -> 46299 | P16: =IF(OR(J16="",L16<TODAY()),999999,L16-TODAY()+ROW()/100000) -> 999999
B17: =IFERROR(_xludf.TEXTJOIN(CHAR(10),TRUE,_xlws.FILTER($K$9:$K$208&" • "&$M$9:$M$208,$L$9:$L$208=B16)),"") | C17: =IFERROR(_xludf.TEXTJOIN(CHAR(10),TRUE,_xlws.FILTER($K$9:$K$208&" • "&$M$9:$M$208,$L$9:$L$208=C16)),"") | D17: =IFERROR(_xludf.TEXTJOIN(CHAR(10),TRUE,_xlws.FILTER($K$9:$K$208&" • "&$M$9:$M$208,$L$9:$L$208=D16)),"") | E17: =IFERROR(_xludf.TEXTJOIN(CHAR(10),TRUE,_xlws.FILTER($K$9:$K$208&" • "&$M$9:$M$208,$L$9:$L$208=E16)),"") | F17: =IFERROR(_xludf.TEXTJOIN(CHAR(10),TRUE,_xlws.FILTER($K$9:$K$208&" • "&$M$9:$M$208,$L$9:$L$208=F16)),"") | G17: =IFERROR(_xludf.TEXTJOIN(CHAR(10),TRUE,_xlws.FILTER($K$9:$K$208&" • "&$M$9:$M$208,$L$9:$L$208=G16)),"") | H17: =IFERROR(_xludf.TEXTJOIN(CHAR(10),TRUE,_xlws.FILTER($K$9:$K$208&" • "&$M$9:$M$208,$L$9:$L$208=H16)),"") | P17: =IF(OR(J17="",L17<TODAY()),999999,L17-TODAY()+ROW()/100000) -> 999999
B18: =H16+1 -> 46300 | C18: =B18+1 -> 46301 | D18: =C18+1 -> 46302 | E18: =D18+1 -> 46303 | F18: =E18+1 -> 46304 | G18: =F18+1 -> 46305 | H18: =G18+1 -> 46306 | P18: =IF(OR(J18="",L18<TODAY()),999999,L18-TODAY()+ROW()/100000) -> 999999
B19: =IFERROR(_xludf.TEXTJOIN(CHAR(10),TRUE,_xlws.FILTER($K$9:$K$208&" • "&$M$9:$M$208,$L$9:$L$208=B18)),"") | C19: =IFERROR(_xludf.TEXTJOIN(CHAR(10),TRUE,_xlws.FILTER($K$9:$K$208&" • "&$M$9:$M$208,$L$9:$L$208=C18)),"") | D19: =IFERROR(_xludf.TEXTJOIN(CHAR(10),TRUE,_xlws.FILTER($K$9:$K$208&" • "&$M$9:$M$208,$L$9:$L$208=D18)),"") | E19: =IFERROR(_xludf.TEXTJOIN(CHAR(10),TRUE,_xlws.FILTER($K$9:$K$208&" • "&$M$9:$M$208,$L$9:$L$208=E18)),"") | F19: =IFERROR(_xludf.TEXTJOIN(CHAR(10),TRUE,_xlws.FILTER($K$9:$K$208&" • "&$M$9:$M$208,$L$9:$L$208=F18)),"") | G19: =IFERROR(_xludf.TEXTJOIN(CHAR(10),TRUE,_xlws.FILTER($K$9:$K$208&" • "&$M$9:$M$208,$L$9:$L$208=G18)),"") | H19: =IFERROR(_xludf.TEXTJOIN(CHAR(10),TRUE,_xlws.FILTER($K$9:$K$208&" • "&$M$9:$M$208,$L$9:$L$208=H18)),"") | P19: =IF(OR(J19="",L19<TODAY()),999999,L19-TODAY()+ROW()/100000) -> 999999
P20: =IF(OR(J20="",L20<TODAY()),999999,L20-TODAY()+ROW()/100000) -> 999999
P21: =IF(OR(J21="",L21<TODAY()),999999,L21-TODAY()+ROW()/100000) -> 999999
P22: =IF(OR(J22="",L22<TODAY()),999999,L22-TODAY()+ROW()/100000) -> 999999
P23: =IF(OR(J23="",L23<TODAY()),999999,L23-TODAY()+ROW()/100000) -> 999999
P24: =IF(OR(J24="",L24<TODAY()),999999,L24-TODAY()+ROW()/100000) -> 999999
P25: =IF(OR(J25="",L25<TODAY()),999999,L25-TODAY()+ROW()/100000) -> 999999
P26: =IF(OR(J26="",L26<TODAY()),999999,L26-TODAY()+ROW()/100000) -> 999999
P27: =IF(OR(J27="",L27<TODAY()),999999,L27-TODAY()+ROW()/100000) -> 999999
P28: =IF(OR(J28="",L28<TODAY()),999999,L28-TODAY()+ROW()/100000) -> 999999
P29: =IF(OR(J29="",L29<TODAY()),999999,L29-TODAY()+ROW()/100000) -> 999999
P30: =IF(OR(J30="",L30<TODAY()),999999,L30-TODAY()+ROW()/100000) -> 999999
P31: =IF(OR(J31="",L31<TODAY()),999999,L31-TODAY()+ROW()/100000) -> 999999
... P208: =IF(OR(J208="",L208<TODAY()),999999,L208-TODAY()+ROW()/100000) -> 999999

Sheet WEEKLY
A1: The Weekly Vibe ♡
A3: Plan what matters. Leave room to be a person.
A5: WEEK OF | B5: 46279
A7: TOP 3 PRIORITIES ✦ | J7: DUE THIS WEEK
A8: 1 | J8: Task | K8: Area | L8: Due | M8: Priority | N8: Status
A9: 2 | J9: {=IF(SMALL(TASKS!$K$6:$K$205,1)>=999999,"",INDEX(TASKS!$A$6:$A$205,MATCH(SMALL(TASKS!$K$6:$K$205,1),TASKS!$K$6:$K$205,0)))} -> Pay electric bill | K9: {=IF(J9="","",INDEX(TASKS!$B$6:$B$205,MATCH(J9,TASKS!$A$6:$A$205,0)))} -> Money | L9: {=IF(J9="","",INDEX(TASKS!$E$6:$E$205,MATCH(J9,TASKS!$A$6:$A$205,0)))} -> 46281 | M9: {=IF(J9="","",INDEX(TASKS!$C$6:$C$205,MATCH(J9,TASKS!$A$6:$A$205,0)))} -> Urgent | N9: {=IF(J9="","",INDEX(TASKS!$F$6:$F$205,MATCH(J9,TASKS!$A$6:$A$205,0)))} -> Not Started
A10: 3 | J10: {=IF(SMALL(TASKS!$K$6:$K$205,2)>=999999,"",INDEX(TASKS!$A$6:$A$205,MATCH(SMALL(TASKS!$K$6:$K$205,2),TASKS!$K$6:$K$205,0)))} -> Plan meals for the week | K10: {=IF(J10="","",INDEX(TASKS!$B$6:$B$205,MATCH(J10,TASKS!$A$6:$A$205,0)))} -> Home | L10: {=IF(J10="","",INDEX(TASKS!$E$6:$E$205,MATCH(J10,TASKS!$A$6:$A$205,0)))} -> 46279 | M10: {=IF(J10="","",INDEX(TASKS!$C$6:$C$205,MATCH(J10,TASKS!$A$6:$A$205,0)))} -> High | N10: {=IF(J10="","",INDEX(TASKS!$F$6:$F$205,MATCH(J10,TASKS!$A$6:$A$205,0)))} -> Not Started
J11: {=IF(SMALL(TASKS!$K$6:$K$205,3)>=999999,"",INDEX(TASKS!$A$6:$A$205,MATCH(SMALL(TASKS!$K$6:$K$205,3),TASKS!$K$6:$K$205,0)))} -> Grocery shopping | K11: {=IF(J11="","",INDEX(TASKS!$B$6:$B$205,MATCH(J11,TASKS!$A$6:$A$205,0)))} -> Home | L11: {=IF(J11="","",INDEX(TASKS!$E$6:$E$205,MATCH(J11,TASKS!$A$6:$A$205,0)))} -> 46283 | M11: {=IF(J11="","",INDEX(TASKS!$C$6:$C$205,MATCH(J11,TASKS!$A$6:$A$205,0)))} -> High | N11: {=IF(J11="","",INDEX(TASKS!$F$6:$F$205,MATCH(J11,TASKS!$A$6:$A$205,0)))} -> Not Started
J12: {=IF(SMALL(TASKS!$K$6:$K$205,4)>=999999,"",INDEX(TASKS!$A$6:$A$205,MATCH(SMALL(TASKS!$K$6:$K$205,4),TASKS!$K$6:$K$205,0)))} -> Workout 30 minutes | K12: {=IF(J12="","",INDEX(TASKS!$B$6:$B$205,MATCH(J12,TASKS!$A$6:$A$205,0)))} -> Health | L12: {=IF(J12="","",INDEX(TASKS!$E$6:$E$205,MATCH(J12,TASKS!$A$6:$A$205,0)))} -> 46280 | M12: {=IF(J12="","",INDEX(TASKS!$C$6:$C$205,MATCH(J12,TASKS!$A$6:$A$205,0)))} -> Medium | N12: {=IF(J12="","",INDEX(TASKS!$F$6:$F$205,MATCH(J12,TASKS!$A$6:$A$205,0)))} -> In Progress
A13: WEEK AT A GLANCE | J13: {=IF(SMALL(TASKS!$K$6:$K$205,5)>=999999,"",INDEX(TASKS!$A$6:$A$205,MATCH(SMALL(TASKS!$K$6:$K$205,5),TASKS!$K$6:$K$205,0)))} -> Organize bedroom | K13: {=IF(J13="","",INDEX(TASKS!$B$6:$B$205,MATCH(J13,TASKS!$A$6:$A$205,0)))} -> Home | L13: {=IF(J13="","",INDEX(TASKS!$E$6:$E$205,MATCH(J13,TASKS!$A$6:$A$205,0)))} -> 46282 | M13: {=IF(J13="","",INDEX(TASKS!$C$6:$C$205,MATCH(J13,TASKS!$A$6:$A$205,0)))} -> Low | N13: {=IF(J13="","",INDEX(TASKS!$F$6:$F$205,MATCH(J13,TASKS!$A$6:$A$205,0)))} -> Not Started
B14: =$B$5+0 -> 46279 | C14: =$B$5+1 -> 46280 | D14: =$B$5+2 -> 46281 | E14: =$B$5+3 -> 46282 | F14: =$B$5+4 -> 46283 | G14: =$B$5+5 -> 46284 | H14: =$B$5+6 -> 46285 | J14: {=IF(SMALL(TASKS!$K$6:$K$205,6)>=999999,"",INDEX(TASKS!$A$6:$A$205,MATCH(SMALL(TASKS!$K$6:$K$205,6),TASKS!$K$6:$K$205,0)))} | K14: {=IF(J14="","",INDEX(TASKS!$B$6:$B$205,MATCH(J14,TASKS!$A$6:$A$205,0)))} | L14: {=IF(J14="","",INDEX(TASKS!$E$6:$E$205,MATCH(J14,TASKS!$A$6:$A$205,0)))} | M14: {=IF(J14="","",INDEX(TASKS!$C$6:$C$205,MATCH(J14,TASKS!$A$6:$A$205,0)))} | N14: {=IF(J14="","",INDEX(TASKS!$F$6:$F$205,MATCH(J14,TASKS!$A$6:$A$205,0)))}
A15: Schedule | J15: {=IF(SMALL(TASKS!$K$6:$K$205,7)>=999999,"",INDEX(TASKS!$A$6:$A$205,MATCH(SMALL(TASKS!$K$6:$K$205,7),TASKS!$K$6:$K$205,0)))} | K15: {=IF(J15="","",INDEX(TASKS!$B$6:$B$205,MATCH(J15,TASKS!$A$6:$A$205,0)))} | L15: {=IF(J15="","",INDEX(TASKS!$E$6:$E$205,MATCH(J15,TASKS!$A$6:$A$205,0)))} | M15: {=IF(J15="","",INDEX(TASKS!$C$6:$C$205,MATCH(J15,TASKS!$A$6:$A$205,0)))} | N15: {=IF(J15="","",INDEX(TASKS!$F$6:$F$205,MATCH(J15,TASKS!$A$6:$A$205,0)))}
A16: Main Task
A17: Meal
A18: Notes | J18: WEEKLY RESET
J19: What feels heavy right now?
J22: What would make this week easier?
J25: What can wait?

Sheet TASKS
A1: Brain Dump + Tasks ♡
A3: Get it out of your head. STV will help decide what needs attention.
A5: Task | B5: Area | C5: Priority | D5: Added | E5: Due | F5: Status | G5: Assigned To | H5: Focus Score | I5: Days Left | J5: Notes | K5: WK
A6: Plan meals for the week | B6: Home | C6: High | D6: 46279 | E6: 46279 | F6: Not Started | G6: Me | H6: =IF(OR(A6="",F6="Done"),999999,IF(C6="Urgent",1,IF(C6="High",2,IF(C6="Medium",3,4)))+IF(E6="",0.9,MAX(0,E6-TODAY())/1000)+ROW()/100000) -> 2.00006 | I6: =IF(E6="","",E6-TODAY()) -> -9 | K6: =IF(OR(A6="",F6="Done",E6<WEEKLY!$B$5,E6>WEEKLY!$B$5+6),999999,H6) -> 2.00006
A7: Pay electric bill | B7: Money | C7: Urgent | D7: 46279 | E7: 46281 | F7: Not Started | G7: Me | H7: =IF(OR(A7="",F7="Done"),999999,IF(C7="Urgent",1,IF(C7="High",2,IF(C7="Medium",3,4)))+IF(E7="",0.9,MAX(0,E7-TODAY())/1000)+ROW()/100000) -> 1.00007 | I7: =IF(E7="","",E7-TODAY()) -> -7 | K7: =IF(OR(A7="",F7="Done",E7<WEEKLY!$B$5,E7>WEEKLY!$B$5+6),999999,H7) -> 1.00007
A8: Workout 30 minutes | B8: Health | C8: Medium | D8: 46279 | E8: 46280 | F8: In Progress | G8: Me | H8: =IF(OR(A8="",F8="Done"),999999,IF(C8="Urgent",1,IF(C8="High",2,IF(C8="Medium",3,4)))+IF(E8="",0.9,MAX(0,E8-TODAY())/1000)+ROW()/100000) -> 3.00008 | I8: =IF(E8="","",E8-TODAY()) -> -8 | K8: =IF(OR(A8="",F8="Done",E8<WEEKLY!$B$5,E8>WEEKLY!$B$5+6),999999,H8) -> 3.00008
A9: Organize bedroom | B9: Home | C9: Low | D9: 46279 | E9: 46282 | F9: Not Started | G9: Me | H9: =IF(OR(A9="",F9="Done"),999999,IF(C9="Urgent",1,IF(C9="High",2,IF(C9="Medium",3,4)))+IF(E9="",0.9,MAX(0,E9-TODAY())/1000)+ROW()/100000) -> 4.00009 | I9: =IF(E9="","",E9-TODAY()) -> -6 | K9: =IF(OR(A9="",F9="Done",E9<WEEKLY!$B$5,E9>WEEKLY!$B$5+6),999999,H9) -> 4.00009
A10: Grocery shopping | B10: Home | C10: High | D10: 46279 | E10: 46283 | F10: Not Started | G10: Me | H10: =IF(OR(A10="",F10="Done"),999999,IF(C10="Urgent",1,IF(C10="High",2,IF(C10="Medium",3,4)))+IF(E10="",0.9,MAX(0,E10-TODAY())/1000)+ROW()/100000) -> 2.0001 | I10: =IF(E10="","",E10-TODAY()) -> -5 | K10: =IF(OR(A10="",F10="Done",E10<WEEKLY!$B$5,E10>WEEKLY!$B$5+6),999999,H10) -> 2.0001
H11: =IF(OR(A11="",F11="Done"),999999,IF(C11="Urgent",1,IF(C11="High",2,IF(C11="Medium",3,4)))+IF(E11="",0.9,MAX(0,E11-TODAY())/1000)+ROW()/100000) -> 999999 | I11: =IF(E11="","",E11-TODAY()) | K11: =IF(OR(A11="",F11="Done",E11<WEEKLY!$B$5,E11>WEEKLY!$B$5+6),999999,H11) -> 999999
H12: =IF(OR(A12="",F12="Done"),999999,IF(C12="Urgent",1,IF(C12="High",2,IF(C12="Medium",3,4)))+IF(E12="",0.9,MAX(0,E12-TODAY())/1000)+ROW()/100000) -> 999999 | I12: =IF(E12="","",E12-TODAY()) | K12: =IF(OR(A12="",F12="Done",E12<WEEKLY!$B$5,E12>WEEKLY!$B$5+6),999999,H12) -> 999999
H13: =IF(OR(A13="",F13="Done"),999999,IF(C13="Urgent",1,IF(C13="High",2,IF(C13="Medium",3,4)))+IF(E13="",0.9,MAX(0,E13-TODAY())/1000)+ROW()/100000) -> 999999 | I13: =IF(E13="","",E13-TODAY()) | K13: =IF(OR(A13="",F13="Done",E13<WEEKLY!$B$5,E13>WEEKLY!$B$5+6),999999,H13) -> 999999
H14: =IF(OR(A14="",F14="Done"),999999,IF(C14="Urgent",1,IF(C14="High",2,IF(C14="Medium",3,4)))+IF(E14="",0.9,MAX(0,E14-TODAY())/1000)+ROW()/100000) -> 999999 | I14: =IF(E14="","",E14-TODAY()) | K14: =IF(OR(A14="",F14="Done",E14<WEEKLY!$B$5,E14>WEEKLY!$B$5+6),999999,H14) -> 999999
H15: =IF(OR(A15="",F15="Done"),999999,IF(C15="Urgent",1,IF(C15="High",2,IF(C15="Medium",3,4)))+IF(E15="",0.9,MAX(0,E15-TODAY())/1000)+ROW()/100000) -> 999999 | I15: =IF(E15="","",E15-TODAY()) | K15: =IF(OR(A15="",F15="Done",E15<WEEKLY!$B$5,E15>WEEKLY!$B$5+6),999999,H15) -> 999999
H16: =IF(OR(A16="",F16="Done"),999999,IF(C16="Urgent",1,IF(C16="High",2,IF(C16="Medium",3,4)))+IF(E16="",0.9,MAX(0,E16-TODAY())/1000)+ROW()/100000) -> 999999 | I16: =IF(E16="","",E16-TODAY()) | K16: =IF(OR(A16="",F16="Done",E16<WEEKLY!$B$5,E16>WEEKLY!$B$5+6),999999,H16) -> 999999
H17: =IF(OR(A17="",F17="Done"),999999,IF(C17="Urgent",1,IF(C17="High",2,IF(C17="Medium",3,4)))+IF(E17="",0.9,MAX(0,E17-TODAY())/1000)+ROW()/100000) -> 999999 | I17: =IF(E17="","",E17-TODAY()) | K17: =IF(OR(A17="",F17="Done",E17<WEEKLY!$B$5,E17>WEEKLY!$B$5+6),999999,H17) -> 999999
H18: =IF(OR(A18="",F18="Done"),999999,IF(C18="Urgent",1,IF(C18="High",2,IF(C18="Medium",3,4)))+IF(E18="",0.9,MAX(0,E18-TODAY())/1000)+ROW()/100000) -> 999999 | I18: =IF(E18="","",E18-TODAY()) | K18: =IF(OR(A18="",F18="Done",E18<WEEKLY!$B$5,E18>WEEKLY!$B$5+6),999999,H18) -> 999999
H19: =IF(OR(A19="",F19="Done"),999999,IF(C19="Urgent",1,IF(C19="High",2,IF(C19="Medium",3,4)))+IF(E19="",0.9,MAX(0,E19-TODAY())/1000)+ROW()/100000) -> 999999 | I19: =IF(E19="","",E19-TODAY()) | K19: =IF(OR(A19="",F19="Done",E19<WEEKLY!$B$5,E19>WEEKLY!$B$5+6),999999,H19) -> 999999
H20: =IF(OR(A20="",F20="Done"),999999,IF(C20="Urgent",1,IF(C20="High",2,IF(C20="Medium",3,4)))+IF(E20="",0.9,MAX(0,E20-TODAY())/1000)+ROW()/100000) -> 999999 | I20: =IF(E20="","",E20-TODAY()) | K20: =IF(OR(A20="",F20="Done",E20<WEEKLY!$B$5,E20>WEEKLY!$B$5+6),999999,H20) -> 999999
H21: =IF(OR(A21="",F21="Done"),999999,IF(C21="Urgent",1,IF(C21="High",2,IF(C21="Medium",3,4)))+IF(E21="",0.9,MAX(0,E21-TODAY())/1000)+ROW()/100000) -> 999999 | I21: =IF(E21="","",E21-TODAY()) | K21: =IF(OR(A21="",F21="Done",E21<WEEKLY!$B$5,E21>WEEKLY!$B$5+6),999999,H21) -> 999999
H22: =IF(OR(A22="",F22="Done"),999999,IF(C22="Urgent",1,IF(C22="High",2,IF(C22="Medium",3,4)))+IF(E22="",0.9,MAX(0,E22-TODAY())/1000)+ROW()/100000) -> 999999 | I22: =IF(E22="","",E22-TODAY()) | K22: =IF(OR(A22="",F22="Done",E22<WEEKLY!$B$5,E22>WEEKLY!$B$5+6),999999,H22) -> 999999
... H205: =IF(OR(A205="",F205="Done"),999999,IF(C205="Urgent",1,IF(C205="High",2,IF(C205="Medium",3,4)))+IF(E205="",0.9,MAX(0,E205-TODAY())/1000)+ROW()/100000) -> 999999 | I205: =IF(E205="","",E205-TODAY()) | K205: =IF(OR(A205="",F205="Done",E205<WEEKLY!$B$5,E205>WEEKLY!$B$5+6),999999,H205) -> 999999

Sheet MONEY
A1: Money Vibe ✦
A3: Know where it went. Know what’s coming. Build what’s next.
A5: MONTH | B5: 46266 | I5: BILLS + SUBSCRIPTIONS
A7: INCOME | C7: SPENDING | E7: SAVINGS ADDED
A8: =SUMIFS($E$14:$E$213,$C$14:$C$213,"Income",$A$14:$A$213,">="&EOMONTH($B$5,-1)+1,$A$14:$A$213,"<="&EOMONTH($B$5,0)) -> 2800 | C8: =SUMIFS($E$14:$E$213,$C$14:$C$213,"Expense",$A$14:$A$213,">="&EOMONTH($B$5,-1)+1,$A$14:$A$213,"<="&EOMONTH($B$5,0)) -> 252.61 | E8: =SUMIFS($E$14:$E$213,$C$14:$C$213,"Savings",$A$14:$A$213,">="&EOMONTH($B$5,-1)+1,$A$14:$A$213,"<="&EOMONTH($B$5,0)) -> 200 | I8: Bill | J8: Due Date | K8: Type | L8: Amount | M8: Status | N8: Autopay | O8: Account | P8: Rank
I9: Electric | J9: 46281 | K9: Bill | L9: 175 | M9: Upcoming | N9: Yes | O9: Checking | P9: =IF(OR(I9="",M9="Paid",J9<TODAY()),999999,J9-TODAY()+ROW()/100000) -> 999999
I10: Streaming | J10: 46285 | K10: Subscription | L10: 21.99 | M10: Paid | N10: Yes | O10: Credit Card | P10: =IF(OR(I10="",M10="Paid",J10<TODAY()),999999,J10-TODAY()+ROW()/100000) -> 999999
I11: Car Insurance | J11: 46291 | K11: Bill | L11: 210 | M11: Upcoming | N11: No | O11: Checking | P11: =IF(OR(I11="",M11="Paid",J11<TODAY()),999999,J11-TODAY()+ROW()/100000) -> 3.00011
A12: TRANSACTIONS | I12: Music | J12: 46293 | K12: Subscription | L12: 10.99 | M12: Upcoming | N12: Yes | O12: Credit Card | P12: =IF(OR(I12="",M12="Paid",J12<TODAY()),999999,J12-TODAY()+ROW()/100000) -> 5.00012
A13: Date | B13: Description | C13: Type | D13: Category | E13: Amount | F13: Account | G13: Notes | P13: =IF(OR(I13="",M13="Paid",J13<TODAY()),999999,J13-TODAY()+ROW()/100000) -> 999999
A14: 46266 | B14: Paycheck | C14: Income | D14: Other | E14: 2800 | F14: Checking | P14: =IF(OR(I14="",M14="Paid",J14<TODAY()),999999,J14-TODAY()+ROW()/100000) -> 999999
A15: 46268 | B15: Groceries | C15: Expense | D15: Groceries | E15: 188.42 | F15: Checking | P15: =IF(OR(I15="",M15="Paid",J15<TODAY()),999999,J15-TODAY()+ROW()/100000) -> 999999
A16: 46270 | B16: Gas | C16: Expense | D16: Transportation | E16: 64.19 | F16: Credit Card | P16: =IF(OR(I16="",M16="Paid",J16<TODAY()),999999,J16-TODAY()+ROW()/100000) -> 999999
A17: 46275 | B17: Savings Transfer | C17: Savings | D17: Savings | E17: 200 | F17: Savings | P17: =IF(OR(I17="",M17="Paid",J17<TODAY()),999999,J17-TODAY()+ROW()/100000) -> 999999
P18: =IF(OR(I18="",M18="Paid",J18<TODAY()),999999,J18-TODAY()+ROW()/100000) -> 999999
P19: =IF(OR(I19="",M19="Paid",J19<TODAY()),999999,J19-TODAY()+ROW()/100000) -> 999999
P20: =IF(OR(I20="",M20="Paid",J20<TODAY()),999999,J20-TODAY()+ROW()/100000) -> 999999
P21: =IF(OR(I21="",M21="Paid",J21<TODAY()),999999,J21-TODAY()+ROW()/100000) -> 999999
P22: =IF(OR(I22="",M22="Paid",J22<TODAY()),999999,J22-TODAY()+ROW()/100000) -> 999999
P23: =IF(OR(I23="",M23="Paid",J23<TODAY()),999999,J23-TODAY()+ROW()/100000) -> 999999
P24: =IF(OR(I24="",M24="Paid",J24<TODAY()),999999,J24-TODAY()+ROW()/100000) -> 999999
P25: =IF(OR(I25="",M25="Paid",J25<TODAY()),999999,J25-TODAY()+ROW()/100000) -> 999999
P26: =IF(OR(I26="",M26="Paid",J26<TODAY()),999999,J26-TODAY()+ROW()/100000) -> 999999
P27: =IF(OR(I27="",M27="Paid",J27<TODAY()),999999,J27-TODAY()+ROW()/100000) -> 999999
P28: =IF(OR(I28="",M28="Paid",J28<TODAY()),999999,J28-TODAY()+ROW()/100000) -> 999999
P29: =IF(OR(I29="",M29="Paid",J29<TODAY()),999999,J29-TODAY()+ROW()/100000) -> 999999
... P208: =IF(OR(I208="",M208="Paid",J208<TODAY()),999999,J208-TODAY()+ROW()/100000) -> 999999
I212: SAVINGS GOALS ✦
I213: Goal | J213: Target | K213: Current | L213: Target Date | M213: Progress | N213: Notes
I214: Emergency Fund | J214: 10000 | K214: 3200 | L214: 46568 | M214: =IFERROR(K214/J214,0) -> 0.32
I215: Vacation | J215: 3500 | K215: 950 | L215: 46508 | M215: =IFERROR(K215/J215,0) -> 0.27142857
M216: =IFERROR(K216/J216,0) -> 0
M217: =IFERROR(K217/J217,0) -> 0
M218: =IFERROR(K218/J218,0) -> 0
M219: =IFERROR(K219/J219,0) -> 0
M220: =IFERROR(K220/J220,0) -> 0
M221: =IFERROR(K221/J221,0) -> 0
M222: =IFERROR(K222/J222,0) -> 0
M223: =IFERROR(K223/J223,0) -> 0
M224: =IFERROR(K224/J224,0) -> 0
...

Sheet HOME
A1: Home Vibe ✦
A3: Keep the house running without letting the house run you.
A5: CLEANING + MAINTENANCE
A7: Task | B7: Room / Area | C7: Frequency | D7: Last Done | E7: Next Due | F7: Status | G7: Assigned To | H7: Notes
A8: Change HVAC filter | B8: Whole House | C8: Monthly | D8: 46266 | E8: 46296 | F8: Not Started | G8: Me
A9: Clean refrigerator | B9: Kitchen | C9: Monthly | D9: 46273 | E9: 46303 | F9: Not Started | G9: Me
A61: WEEKLY MEAL PLAN
A63: Meal | B63: Monday | C63: Tuesday | D63: Wednesday | E63: Thursday | F63: Friday | G63: Saturday | H63: Sunday
A64: Breakfast
A65: Lunch
A66: Dinner
A67: Snacks
A71: GROCERY + HOME INVENTORY
A73: Item | B73: Category | C73: On Hand | D73: Need | E73: Unit | F73: Restock? | G73: Store / Location | H73: Notes
A74: Eggs | B74: Groceries | C74: 6 | D74: 12 | E74: each | F74: Yes | G74: Grocery Store
A75: Paper Towels | B75: Home | C75: 2 | D75: 6 | E75: rolls | F75: Yes | G75: Warehouse

Sheet FAMILY
A1: Family Command Center ♡
A3: Keep the people you love organized without keeping it all in your head.
A5: IMPORTANT INFO
A7: Person | B7: School / Provider | C7: Birthday | D7: Phone | E7: Allergies / Notes | F7: Activity | G7: Schedule / Details | H7: Extra Notes
A8: Alex | B8: Oak Grove School | C8: 43008 | E8: None | F8: Soccer | G8: Tue/Thu 5 PM
A9: Mia | B9: Preschool | C9: 45028 | E9: Food dye sensitivity | F9: Dance | G9: Saturday 10 AM
A61: SCHOOL + ACTIVITY DATES
A63: Person | B63: Event | C63: Date | D63: Time | E63: Type | F63: Location | G63: What to Bring | H63: Notes
A64: Alex | B64: Picture Day | C64: 46289 | D64: 8:00 AM | E64: School | F64: Campus | G64: Picture form
A65: Mia | B65: Family Day | C65: 46297 | D65: 10:00 AM | E65: School | F65: Preschool
A66: Family | B66: Fall Festival | C66: 46311 | D66: 5:30 PM | E66: Activity | F66: Community Center

Sheet GOALS
A1: Goals + Milestones ✦
A3: Big vision. Clear next move. Pretty progress.
A5: Goal | B5: Area | C5: Why It Matters | D5: Target Date | E5: Progress | F5: Status | G5: Next Milestone | H5: Next Action | I5: Rank
A6: Build emergency fund | B6: Money | C6: More breathing room and options | D6: 46568 | E6: 0.32 | F6: In Progress | G6: Reach $4,000 | H6: Transfer $200 | I6: =IF(OR(A6="",F6="Complete"),999999,MAX(0,D6-TODAY())+ROW()/100000) -> 280.00006
A7: Create a calmer home routine | B7: Home | C7: Less mental clutter | D7: 46387 | E7: 0.45 | F7: In Progress | G7: Lock weekly reset | H7: Test Sunday reset | I7: =IF(OR(A7="",F7="Complete"),999999,MAX(0,D7-TODAY())+ROW()/100000) -> 99.00007
A8: Read 12 books | B8: Personal | C8: Make time for myself | D8: 46387 | E8: 0.5 | F8: In Progress | G8: Finish book 7 | H8: Choose next title | I8: =IF(OR(A8="",F8="Complete"),999999,MAX(0,D8-TODAY())+ROW()/100000) -> 99.00008
I9: =IF(OR(A9="",F9="Complete"),999999,MAX(0,D9-TODAY())+ROW()/100000) -> 999999
I10: =IF(OR(A10="",F10="Complete"),999999,MAX(0,D10-TODAY())+ROW()/100000) -> 999999
I11: =IF(OR(A11="",F11="Complete"),999999,MAX(0,D11-TODAY())+ROW()/100000) -> 999999
I12: =IF(OR(A12="",F12="Complete"),999999,MAX(0,D12-TODAY())+ROW()/100000) -> 999999
I13: =IF(OR(A13="",F13="Complete"),999999,MAX(0,D13-TODAY())+ROW()/100000) -> 999999
I14: =IF(OR(A14="",F14="Complete"),999999,MAX(0,D14-TODAY())+ROW()/100000) -> 999999
I15: =IF(OR(A15="",F15="Complete"),999999,MAX(0,D15-TODAY())+ROW()/100000) -> 999999
I16: =IF(OR(A16="",F16="Complete"),999999,MAX(0,D16-TODAY())+ROW()/100000) -> 999999
I17: =IF(OR(A17="",F17="Complete"),999999,MAX(0,D17-TODAY())+ROW()/100000) -> 999999
I18: =IF(OR(A18="",F18="Complete"),999999,MAX(0,D18-TODAY())+ROW()/100000) -> 999999
I19: =IF(OR(A19="",F19="Complete"),999999,MAX(0,D19-TODAY())+ROW()/100000) -> 999999
I20: =IF(OR(A20="",F20="Complete"),999999,MAX(0,D20-TODAY())+ROW()/100000) -> 999999
... I105: =IF(OR(A105="",F105="Complete"),999999,MAX(0,D105-TODAY())+ROW()/100000) -> 999999

Sheet SETTINGS
A1: STV Settings ✦
A3: Make it yours once. Let the workbook do the rest.
A5: PRIORITY | B5: TASK STATUS | C5: LIFE AREA | D5: EVENT TYPE | E5: MONEY CATEGORY | F5: BILL STATUS | G5: TRANSACTION TYPE | H5: GOAL STATUS
A6: Low | B6: Not Started | C6: Personal | D6: Appointment | E6: Housing | F6: Upcoming | G6: Income | H6: Not Started
A7: Medium | B7: In Progress | C7: Family | D7: School | E7: Utilities | F7: Paid | G7: Expense | H7: In Progress
A8: High | B8: Waiting | C8: Home | D8: Activity | E8: Groceries | F8: Late | G8: Savings | H8: Paused
A9: Urgent | B9: Done | C9: Money | D9: Birthday | E9: Dining | F9: Skipped | H9: Complete
B10: Someday | C10: Work | D10: Deadline | E10: Transportation | H10: Someday
C11: Health | D11: Personal | E11: Kids
C12: School | D12: Other | E12: Health
C13: Other | E13: Personal
E14: Subscriptions
E15: Debt
E16: Savings
E17: Home
E18: Other
A21: STV COLOR KEY ✦
A22: BURGUNDY | B22: #6B1028 | C22: Primary headers | E22: CREAM | F22: #FFF8EE | G22: Main background
A23: WINE | B23: #8D2442 | C23: Secondary accent | E23: GOLD | F23: #D5AE5E | G23: Luxury accent
A24: BLUSH | B24: #F2D9DE | C24: Soft sections | E24: WHITE | F24: #FFFFFF | G24: Data entry
A25: SAGE | B25: #C9D7C4 | C25: Complete / positive | E25: PEACH | F25: #F3D0B9 | G25: In progress
A27: STV | B27: She's the Vibe | C27: Cute. Luxe. Useful.
